[02-17-2021-18-04-52][LOG]: #168782 Start
[02-17-2021-18-05-10][LOG]: #168782 Logged In
[02-17-2021-18-05-13][EXCEPTION]: Traceback (most recent call last):
  File "/home/ubuntu/projects/zeus/src/application/spotify/listener.py", line 158, in runner
    spotify.playPlaylist(t_context.playlist, self.p_context.shutdownEvent, 90, 110)
  File "/home/ubuntu/projects/zeus/src/application/spotify/Spotify.py", line 81, in playPlaylist
    self.driver.get(playlist_url)
  File "/home/ubuntu/.local/lib/python3.9/site-packages/selenium/webdriver/remote/webdriver.py", line 333, in get
    self.execute(Command.GET, {'url': url})
  File "/home/ubuntu/.local/lib/python3.9/site-packages/selenium/webdriver/remote/webdriver.py", line 321, in execute
    self.error_handler.check_response(response)
  File "/home/ubuntu/.local/lib/python3.9/site-packages/selenium/webdriver/remote/errorhandler.py", line 242, in check_response
    raise exception_class(message, screen, stacktrace)
selenium.common.exceptions.WebDriverException: Message: unknown error: net::ERR_TUNNEL_CONNECTION_FAILED
  (Session info: chrome=85.0.4183.83)


