02-13-2021-15-58-36[ss][EXCEPTION]: Traceback (most recent call last):
  File "/home/ubuntu/projects/zeus/src/services/driversadapter/chrome.py", line 121, in getNewInstance
    driver = webdriver.Remote(self.service.service_url, desired_capabilities=desired_capabilities, options=options)
  File "/home/ubuntu/.local/lib/python3.9/site-packages/selenium/webdriver/remote/webdriver.py", line 157, in __init__
    self.start_session(capabilities, browser_profile)
  File "/home/ubuntu/.local/lib/python3.9/site-packages/selenium/webdriver/remote/webdriver.py", line 252, in start_session
    response = self.execute(Command.NEW_SESSION, parameters)
  File "/home/ubuntu/.local/lib/python3.9/site-packages/selenium/webdriver/remote/webdriver.py", line 321, in execute
    self.error_handler.check_response(response)
  File "/home/ubuntu/.local/lib/python3.9/site-packages/selenium/webdriver/remote/errorhandler.py", line 242, in check_response
    raise exception_class(message, screen, stacktrace)
selenium.common.exceptions.WebDriverException: Message: unknown error: Chrome failed to start: exited abnormally.
  (unknown error: DevToolsActivePort file doesn't exist)
  (The process started from chrome location /usr/bin/google-chrome is no longer running, so ChromeDriver is assuming that Chrome has crashed.)


02-13-2021-15-59-00[ss][EXCEPTION]: Traceback (most recent call last):
  File "/home/ubuntu/projects/zeus/src/services/driversadapter/chrome.py", line 121, in getNewInstance
    driver = webdriver.Remote(self.service.service_url, desired_capabilities=desired_capabilities, options=options)
  File "/home/ubuntu/.local/lib/python3.9/site-packages/selenium/webdriver/remote/webdriver.py", line 157, in __init__
    self.start_session(capabilities, browser_profile)
  File "/home/ubuntu/.local/lib/python3.9/site-packages/selenium/webdriver/remote/webdriver.py", line 252, in start_session
    response = self.execute(Command.NEW_SESSION, parameters)
  File "/home/ubuntu/.local/lib/python3.9/site-packages/selenium/webdriver/remote/webdriver.py", line 321, in execute
    self.error_handler.check_response(response)
  File "/home/ubuntu/.local/lib/python3.9/site-packages/selenium/webdriver/remote/errorhandler.py", line 242, in check_response
    raise exception_class(message, screen, stacktrace)
selenium.common.exceptions.WebDriverException: Message: unknown error: Chrome failed to start: exited abnormally.
  (unknown error: DevToolsActivePort file doesn't exist)
  (The process started from chrome location /usr/bin/google-chrome is no longer running, so ChromeDriver is assuming that Chrome has crashed.)


02-13-2021-15-59-05[ss][EXCEPTION]: Traceback (most recent call last):
  File "/home/ubuntu/projects/zeus/src/services/driversadapter/chrome.py", line 121, in getNewInstance
    driver = webdriver.Remote(self.service.service_url, desired_capabilities=desired_capabilities, options=options)
  File "/home/ubuntu/.local/lib/python3.9/site-packages/selenium/webdriver/remote/webdriver.py", line 157, in __init__
    self.start_session(capabilities, browser_profile)
  File "/home/ubuntu/.local/lib/python3.9/site-packages/selenium/webdriver/remote/webdriver.py", line 252, in start_session
    response = self.execute(Command.NEW_SESSION, parameters)
  File "/home/ubuntu/.local/lib/python3.9/site-packages/selenium/webdriver/remote/webdriver.py", line 321, in execute
    self.error_handler.check_response(response)
  File "/home/ubuntu/.local/lib/python3.9/site-packages/selenium/webdriver/remote/errorhandler.py", line 242, in check_response
    raise exception_class(message, screen, stacktrace)
selenium.common.exceptions.WebDriverException: Message: unknown error: Chrome failed to start: exited abnormally.
  (unknown error: DevToolsActivePort file doesn't exist)
  (The process started from chrome location /usr/bin/google-chrome is no longer running, so ChromeDriver is assuming that Chrome has crashed.)


02-13-2021-15-59-10[ss][EXCEPTION]: Traceback (most recent call last):
  File "/home/ubuntu/projects/zeus/src/services/driversadapter/chrome.py", line 121, in getNewInstance
    driver = webdriver.Remote(self.service.service_url, desired_capabilities=desired_capabilities, options=options)
  File "/home/ubuntu/.local/lib/python3.9/site-packages/selenium/webdriver/remote/webdriver.py", line 157, in __init__
    self.start_session(capabilities, browser_profile)
  File "/home/ubuntu/.local/lib/python3.9/site-packages/selenium/webdriver/remote/webdriver.py", line 252, in start_session
    response = self.execute(Command.NEW_SESSION, parameters)
  File "/home/ubuntu/.local/lib/python3.9/site-packages/selenium/webdriver/remote/webdriver.py", line 321, in execute
    self.error_handler.check_response(response)
  File "/home/ubuntu/.local/lib/python3.9/site-packages/selenium/webdriver/remote/errorhandler.py", line 242, in check_response
    raise exception_class(message, screen, stacktrace)
selenium.common.exceptions.WebDriverException: Message: unknown error: Chrome failed to start: exited abnormally.
  (unknown error: DevToolsActivePort file doesn't exist)
  (The process started from chrome location /usr/bin/google-chrome is no longer running, so ChromeDriver is assuming that Chrome has crashed.)


02-13-2021-15-59-16[ss][EXCEPTION]: Traceback (most recent call last):
  File "/home/ubuntu/projects/zeus/src/services/drivers.py", line 27, in getDriver
    raise Exception("getDriver return None")
Exception: getDriver return None

02-13-2021-15-59-30[ss][EXCEPTION]: Traceback (most recent call last):
  File "/home/ubuntu/projects/zeus/src/services/driversadapter/chrome.py", line 121, in getNewInstance
    driver = webdriver.Remote(self.service.service_url, desired_capabilities=desired_capabilities, options=options)
  File "/home/ubuntu/.local/lib/python3.9/site-packages/selenium/webdriver/remote/webdriver.py", line 157, in __init__
    self.start_session(capabilities, browser_profile)
  File "/home/ubuntu/.local/lib/python3.9/site-packages/selenium/webdriver/remote/webdriver.py", line 252, in start_session
    response = self.execute(Command.NEW_SESSION, parameters)
  File "/home/ubuntu/.local/lib/python3.9/site-packages/selenium/webdriver/remote/webdriver.py", line 321, in execute
    self.error_handler.check_response(response)
  File "/home/ubuntu/.local/lib/python3.9/site-packages/selenium/webdriver/remote/errorhandler.py", line 242, in check_response
    raise exception_class(message, screen, stacktrace)
selenium.common.exceptions.WebDriverException: Message: unknown error: Chrome failed to start: exited abnormally.
  (unknown error: DevToolsActivePort file doesn't exist)
  (The process started from chrome location /usr/bin/google-chrome is no longer running, so ChromeDriver is assuming that Chrome has crashed.)


