02-13-2021-00-30-29[ss][EXCEPTION]: Traceback (most recent call last):
  File "sp-register.py", line 49, in runner
    client.send_message(
  File "/home/ubuntu/.local/lib/python3.9/site-packages/botocore/client.py", line 357, in _api_call
    return self._make_api_call(operation_name, kwargs)
  File "/home/ubuntu/.local/lib/python3.9/site-packages/botocore/client.py", line 662, in _make_api_call
    http, parsed_response = self._make_request(
  File "/home/ubuntu/.local/lib/python3.9/site-packages/botocore/client.py", line 682, in _make_request
    return self._endpoint.make_request(operation_model, request_dict)
  File "/home/ubuntu/.local/lib/python3.9/site-packages/botocore/endpoint.py", line 102, in make_request
    return self._send_request(request_dict, operation_model)
  File "/home/ubuntu/.local/lib/python3.9/site-packages/botocore/endpoint.py", line 132, in _send_request
    request = self.create_request(request_dict, operation_model)
  File "/home/ubuntu/.local/lib/python3.9/site-packages/botocore/endpoint.py", line 115, in create_request
    self._event_emitter.emit(event_name, request=request,
  File "/home/ubuntu/.local/lib/python3.9/site-packages/botocore/hooks.py", line 356, in emit
    return self._emitter.emit(aliased_event_name, **kwargs)
  File "/home/ubuntu/.local/lib/python3.9/site-packages/botocore/hooks.py", line 228, in emit
    return self._emit(event_name, kwargs)
  File "/home/ubuntu/.local/lib/python3.9/site-packages/botocore/hooks.py", line 211, in _emit
    response = handler(**kwargs)
  File "/home/ubuntu/.local/lib/python3.9/site-packages/botocore/signers.py", line 90, in handler
    return self.sign(operation_name, request)
  File "/home/ubuntu/.local/lib/python3.9/site-packages/botocore/signers.py", line 162, in sign
    auth.add_auth(request)
  File "/home/ubuntu/.local/lib/python3.9/site-packages/botocore/auth.py", line 357, in add_auth
    raise NoCredentialsError
botocore.exceptions.NoCredentialsError: Unable to locate credentials


