[02-17-2021-18-00-45][LOG]: #168174 Start
[02-17-2021-18-00-46][EXCEPTION]: Traceback (most recent call last):
  File "/home/ubuntu/projects/zeus/src/application/spotify/listener.py", line 155, in runner
    if spotify.login(t_context.user['email'], t_context.user['password']):
  File "/home/ubuntu/projects/zeus/src/application/spotify/Spotify.py", line 40, in login
    self.driver.get(LOGIN_URL)
  File "/home/ubuntu/.local/lib/python3.9/site-packages/selenium/webdriver/remote/webdriver.py", line 333, in get
    self.execute(Command.GET, {'url': url})
  File "/home/ubuntu/.local/lib/python3.9/site-packages/selenium/webdriver/remote/webdriver.py", line 321, in execute
    self.error_handler.check_response(response)
  File "/home/ubuntu/.local/lib/python3.9/site-packages/selenium/webdriver/remote/errorhandler.py", line 242, in check_response
    raise exception_class(message, screen, stacktrace)
selenium.common.exceptions.WebDriverException: Message: unknown error: net::ERR_TUNNEL_CONNECTION_FAILED
  (Session info: chrome=85.0.4183.83)


